{"failedCount":1,"prefixedPath":"src\/test\/java\/payments\/post\/create_payments-post.feature","packageQualifiedName":"src.test.java.payments.post.create_payments-post","loopIndex":-1,"relativePath":"src\/test\/java\/payments\/post\/create_payments-post.feature","scenarioResults":[{"sectionIndex":0,"stepResults":[{"result":{"nanos":3776764000,"errorMessage":"status code was: 500, expected: 200, response time in milliseconds: 1243, url: https:\/\/funcoeback-dev-ceqh.3.us-1.fl0.io\/users\/token\/, response: \nTraceback (most recent call last):\n  File \"\/layers\/paketo-buildpacks_pip-install\/packages\/lib\/python3.10\/site-packages\/sqlalchemy\/engine\/base.py\", line 1969, in _exec_single_context\n    self.dialect.do_execute(\n  File \"\/layers\/paketo-buildpacks_pip-install\/packages\/lib\/python3.10\/site-packages\/sqlalchemy\/engine\/default.py\", line 922, in do_execute\n    cursor.execute(statement, parameters)\n  File \"\/layers\/paketo-buildpacks_pip-install\/packages\/lib\/python3.10\/site-packages\/pymysql\/cursors.py\", line 153, in execute\n    result = self._query(query)\n  File \"\/layers\/paketo-buildpacks_pip-install\/packages\/lib\/python3.10\/site-packages\/pymysql\/cursors.py\", line 322, in _query\n    conn.query(q)\n  File \"\/layers\/paketo-buildpacks_pip-install\/packages\/lib\/python3.10\/site-packages\/pymysql\/connections.py\", line 558, in query\n    self._affected_rows = self._read_query_result(unbuffered=unbuffered)\n  File \"\/layers\/paketo-buildpacks_pip-install\/packages\/lib\/python3.10\/site-packages\/pymysql\/connections.py\", line 822, in _read_query_result\n    result.read()\n  File \"\/layers\/paketo-buildpacks_pip-install\/packages\/lib\/python3.10\/site-packages\/pymysql\/connections.py\", line 1200, in read\n    first_packet = self.connection._read_packet()\n  File \"\/layers\/paketo-buildpacks_pip-install\/packages\/lib\/python3.10\/site-packages\/pymysql\/connections.py\", line 739, in _read_packet\n    packet_header = self._read_bytes(4)\n  File \"\/layers\/paketo-buildpacks_pip-install\/packages\/lib\/python3.10\/site-packages\/pymysql\/connections.py\", line 795, in _read_bytes\n    raise err.OperationalError(\npymysql.err.OperationalError: (2013, 'Lost connection to MySQL server during query')\n\nThe above exception was the direct cause of the following exception:\n\nTraceback (most recent call last):\n  File \"\/layers\/paketo-buildpacks_pip-install\/packages\/lib\/python3.10\/site-packages\/starlette\/middleware\/errors.py\", line 164, in __call__\n    await self.app(scope, receive, _send)\n  File \"\/layers\/paketo-buildpacks_pip-install\/packages\/lib\/python3.10\/site-packages\/starlette\/middleware\/exceptions.py\", line 62, in __call__\n    await wrap_app_handling_exceptions(self.app, conn)(scope, receive, send)\n  File \"\/layers\/paketo-buildpacks_pip-install\/packages\/lib\/python3.10\/site-packages\/starlette\/_exception_handler.py\", line 64, in wrapped_app\n    raise exc\n  File \"\/layers\/paketo-buildpacks_pip-install\/packages\/lib\/python3.10\/site-packages\/starlette\/_exception_handler.py\", line 53, in wrapped_app\n    await app(scope, receive, sender)\n  File \"\/layers\/paketo-buildpacks_pip-install\/packages\/lib\/python3.10\/site-packages\/starlette\/routing.py\", line 762, in __call__\n    await self.middleware_stack(scope, receive, send)\n  File \"\/layers\/paketo-buildpacks_pip-install\/packages\/lib\/python3.10\/site-packages\/starlette\/routing.py\", line 782, in app\n    await route.handle(scope, receive, send)\n  File \"\/layers\/paketo-buildpacks_pip-install\/packages\/lib\/python3.10\/site-packages\/starlette\/routing.py\", line 297, in handle\n    await self.app(scope, receive, send)\n  File \"\/layers\/paketo-buildpacks_pip-install\/packages\/lib\/python3.10\/site-packages\/starlette\/routing.py\", line 77, in app\n    await wrap_app_handling_exceptions(app, request)(scope, receive, send)\n  File \"\/layers\/paketo-buildpacks_pip-install\/packages\/lib\/python3.10\/site-packages\/starlette\/_exception_handler.py\", line 64, in wrapped_app\n    raise exc\n  File \"\/layers\/paketo-buildpacks_pip-install\/packages\/lib\/python3.10\/site-packages\/starlette\/_exception_handler.py\", line 53, in wrapped_app\n    await app(scope, receive, sender)\n  File \"\/layers\/paketo-buildpacks_pip-install\/packages\/lib\/python3.10\/site-packages\/starlette\/routing.py\", line 72, in app\n    response = await func(request)\n  File \"\/layers\/paketo-buildpacks_pip-install\/packages\/lib\/python3.10\/site-packages\/fastapi\/routing.py\", line 299, in app\n    raise e\n  File \"\/layers\/paketo-buildpacks_pip-install\/packages\/lib\/python3.10\/site-packages\/fastapi\/routing.py\", line 294, in app\n    raw_response = await run_endpoint_function(\n  File \"\/layers\/paketo-buildpacks_pip-install\/packages\/lib\/python3.10\/site-packages\/fastapi\/routing.py\", line 193, in run_endpoint_function\n    return await run_in_threadpool(dependant.call, **values)\n  File \"\/layers\/paketo-buildpacks_pip-install\/packages\/lib\/python3.10\/site-packages\/starlette\/concurrency.py\", line 40, in run_in_threadpool\n    return await anyio.to_thread.run_sync(func, *args)\n  File \"\/layers\/paketo-buildpacks_pip-install\/packages\/lib\/python3.10\/site-packages\/anyio\/to_thread.py\", line 56, in run_sync\n    return await get_async_backend().run_sync_in_worker_thread(\n  File \"\/layers\/paketo-buildpacks_pip-install\/packages\/lib\/python3.10\/site-packages\/anyio\/_backends\/_asyncio.py\", line 2134, in run_sync_in_worker_thread\n    return await future\n  File \"\/layers\/paketo-buildpacks_pip-install\/packages\/lib\/python3.10\/site-packages\/anyio\/_backends\/_asyncio.py\", line 851, in run\n    result = context.run(func, *args)\n  File \"\/workspace\/app\/routes\/user.py\", line 19, in get_token\n    if validate_user(user):\n  File \"\/workspace\/app\/func\/user.py\", line 26, in validate_user\n    r1=db.query(user_model).where(user_model.uuid_user==id_user).one()\n  File \"\/layers\/paketo-buildpacks_pip-install\/packages\/lib\/python3.10\/site-packages\/sqlalchemy\/orm\/query.py\", line 2798, in one\n    return self._iter().one()  # type: ignore\n  File \"\/layers\/paketo-buildpacks_pip-install\/packages\/lib\/python3.10\/site-packages\/sqlalchemy\/orm\/query.py\", line 2847, in _iter\n    result: Union[ScalarResult[_T], Result[_T]] = self.session.execute(\n  File \"\/layers\/paketo-buildpacks_pip-install\/packages\/lib\/python3.10\/site-packages\/sqlalchemy\/orm\/session.py\", line 2308, in execute\n    return self._execute_internal(\n  File \"\/layers\/paketo-buildpacks_pip-install\/packages\/lib\/python3.10\/site-packages\/sqlalchemy\/orm\/session.py\", line 2190, in _execute_internal\n    result: Result[Any] = compile_state_cls.orm_execute_statement(\n  File \"\/layers\/paketo-buildpacks_pip-install\/packages\/lib\/python3.10\/site-packages\/sqlalchemy\/orm\/context.py\", line 293, in orm_execute_statement\n    result = conn.execute(\n  File \"\/layers\/paketo-buildpacks_pip-install\/packages\/lib\/python3.10\/site-packages\/sqlalchemy\/engine\/base.py\", line 1416, in execute\n    return meth(\n  File \"\/layers\/paketo-buildpacks_pip-install\/packages\/lib\/python3.10\/site-packages\/sqlalchemy\/sql\/elements.py\", line 517, in _execute_on_connection\n    return connection._execute_clauseelement(\n  File \"\/layers\/paketo-buildpacks_pip-install\/packages\/lib\/python3.10\/site-packages\/sqlalchemy\/engine\/base.py\", line 1639, in _execute_clauseelement\n    ret = self._execute_context(\n  File \"\/layers\/paketo-buildpacks_pip-install\/packages\/lib\/python3.10\/site-packages\/sqlalchemy\/engine\/base.py\", line 1848, in _execute_context\n    return self._exec_single_context(\n  File \"\/layers\/paketo-buildpacks_pip-install\/packages\/lib\/python3.10\/site-packages\/sqlalchemy\/engine\/base.py\", line 1988, in _exec_single_context\n    self._handle_dbapi_exception(\n  File \"\/layers\/paketo-buildpacks_pip-install\/packages\/lib\/python3.10\/site-packages\/sqlalchemy\/engine\/base.py\", line 2344, in _handle_dbapi_exception\n    raise sqlalchemy_exception.with_traceback(exc_info[2]) from e\n  File \"\/layers\/paketo-buildpacks_pip-install\/packages\/lib\/python3.10\/site-packages\/sqlalchemy\/engine\/base.py\", line 1969, in _exec_single_context\n    self.dialect.do_execute(\n  File \"\/layers\/paketo-buildpacks_pip-install\/packages\/lib\/python3.10\/site-packages\/sqlalchemy\/engine\/default.py\", line 922, in do_execute\n    cursor.execute(statement, parameters)\n  File \"\/layers\/paketo-buildpacks_pip-install\/packages\/lib\/python3.10\/site-packages\/pymysql\/cursors.py\", line 153, in execute\n    result = self._query(query)\n  File \"\/layers\/paketo-buildpacks_pip-install\/packages\/lib\/python3.10\/site-packages\/pymysql\/cursors.py\", line 322, in _query\n    conn.query(q)\n  File \"\/layers\/paketo-buildpacks_pip-install\/packages\/lib\/python3.10\/site-packages\/pymysql\/connections.py\", line 558, in query\n    self._affected_rows = self._read_query_result(unbuffered=unbuffered)\n  File \"\/layers\/paketo-buildpacks_pip-install\/packages\/lib\/python3.10\/site-packages\/pymysql\/connections.py\", line 822, in _read_query_result\n    result.read()\n  File \"\/layers\/paketo-buildpacks_pip-install\/packages\/lib\/python3.10\/site-packages\/pymysql\/connections.py\", line 1200, in read\n    first_packet = self.connection._read_packet()\n  File \"\/layers\/paketo-buildpacks_pip-install\/packages\/lib\/python3.10\/site-packages\/pymysql\/connections.py\", line 739, in _read_packet\n    packet_header = self._read_bytes(4)\n  File \"\/layers\/paketo-buildpacks_pip-install\/packages\/lib\/python3.10\/site-packages\/pymysql\/connections.py\", line 795, in _read_bytes\n    raise err.OperationalError(\nsqlalchemy.exc.OperationalError: (pymysql.err.OperationalError) (2013, 'Lost connection to MySQL server during query')\n[SQL: SELECT users.uuid_user AS users_uuid_user, users.user AS users_user, users.password AS users_password, users.rol_uuid AS users_rol_uuid, users.is_active AS users_is_active, users.last_connection AS users_last_connection, users.created_at AS users_created_at, users.updated_at AS users_updated_at \nFROM users \nWHERE users.uuid_user = %(uuid_user_1)s]\n[parameters: {'uuid_user_1': 'a0ce19ba-1824-478e-800b-8d8ae78cc608'}]\n(Background on this error at: https:\/\/sqlalche.me\/e\/20\/e3q8)\n\nsrc\/test\/java\/payments\/post\/..\/..\/user\/token\/users-token-post.feature:9\nsrc\/test\/java\/payments\/post\/create_payments-post.feature:5","millis":3776.764,"status":"failed"},"step":{"background":true,"line":5,"prefix":"*","index":0,"text":"call read(\"..\/..\/user\/token\/users-token-post.feature@token\")"},"stepLog":"22:15:29.969 src\/test\/java\/payments\/post\/create_payments-post.feature:5\n* call read(\"..\/..\/user\/token\/users-token-post.feature@token\")\nstatus code was: 500, expected: 200, response time in milliseconds: 1243, url: https:\/\/funcoeback-dev-ceqh.3.us-1.fl0.io\/users\/token\/, response: \nTraceback (most recent call last):\n  File \"\/layers\/paketo-buildpacks_pip-install\/packages\/lib\/python3.10\/site-packages\/sqlalchemy\/engine\/base.py\", line 1969, in _exec_single_context\n    self.dialect.do_execute(\n  File \"\/layers\/paketo-buildpacks_pip-install\/packages\/lib\/python3.10\/site-packages\/sqlalchemy\/engine\/default.py\", line 922, in do_execute\n    cursor.execute(statement, parameters)\n  File \"\/layers\/paketo-buildpacks_pip-install\/packages\/lib\/python3.10\/site-packages\/pymysql\/cursors.py\", line 153, in execute\n    result = self._query(query)\n  File \"\/layers\/paketo-buildpacks_pip-install\/packages\/lib\/python3.10\/site-packages\/pymysql\/cursors.py\", line 322, in _query\n    conn.query(q)\n  File \"\/layers\/paketo-buildpacks_pip-install\/packages\/lib\/python3.10\/site-packages\/pymysql\/connections.py\", line 558, in query\n    self._affected_rows = self._read_query_result(unbuffered=unbuffered)\n  File \"\/layers\/paketo-buildpacks_pip-install\/packages\/lib\/python3.10\/site-packages\/pymysql\/connections.py\", line 822, in _read_query_result\n    result.read()\n  File \"\/layers\/paketo-buildpacks_pip-install\/packages\/lib\/python3.10\/site-packages\/pymysql\/connections.py\", line 1200, in read\n    first_packet = self.connection._read_packet()\n  File \"\/layers\/paketo-buildpacks_pip-install\/packages\/lib\/python3.10\/site-packages\/pymysql\/connections.py\", line 739, in _read_packet\n    packet_header = self._read_bytes(4)\n  File \"\/layers\/paketo-buildpacks_pip-install\/packages\/lib\/python3.10\/site-packages\/pymysql\/connections.py\", line 795, in _read_bytes\n    raise err.OperationalError(\npymysql.err.OperationalError: (2013, 'Lost connection to MySQL server during query')\n\nThe above exception was the direct cause of the following exception:\n\nTraceback (most recent call last):\n  File \"\/layers\/paketo-buildpacks_pip-install\/packages\/lib\/python3.10\/site-packages\/starlette\/middleware\/errors.py\", line 164, in __call__\n    await self.app(scope, receive, _send)\n  File \"\/layers\/paketo-buildpacks_pip-install\/packages\/lib\/python3.10\/site-packages\/starlette\/middleware\/exceptions.py\", line 62, in __call__\n    await wrap_app_handling_exceptions(self.app, conn)(scope, receive, send)\n  File \"\/layers\/paketo-buildpacks_pip-install\/packages\/lib\/python3.10\/site-packages\/starlette\/_exception_handler.py\", line 64, in wrapped_app\n    raise exc\n  File \"\/layers\/paketo-buildpacks_pip-install\/packages\/lib\/python3.10\/site-packages\/starlette\/_exception_handler.py\", line 53, in wrapped_app\n    await app(scope, receive, sender)\n  File \"\/layers\/paketo-buildpacks_pip-install\/packages\/lib\/python3.10\/site-packages\/starlette\/routing.py\", line 762, in __call__\n    await self.middleware_stack(scope, receive, send)\n  File \"\/layers\/paketo-buildpacks_pip-install\/packages\/lib\/python3.10\/site-packages\/starlette\/routing.py\", line 782, in app\n    await route.handle(scope, receive, send)\n  File \"\/layers\/paketo-buildpacks_pip-install\/packages\/lib\/python3.10\/site-packages\/starlette\/routing.py\", line 297, in handle\n    await self.app(scope, receive, send)\n  File \"\/layers\/paketo-buildpacks_pip-install\/packages\/lib\/python3.10\/site-packages\/starlette\/routing.py\", line 77, in app\n    await wrap_app_handling_exceptions(app, request)(scope, receive, send)\n  File \"\/layers\/paketo-buildpacks_pip-install\/packages\/lib\/python3.10\/site-packages\/starlette\/_exception_handler.py\", line 64, in wrapped_app\n    raise exc\n  File \"\/layers\/paketo-buildpacks_pip-install\/packages\/lib\/python3.10\/site-packages\/starlette\/_exception_handler.py\", line 53, in wrapped_app\n    await app(scope, receive, sender)\n  File \"\/layers\/paketo-buildpacks_pip-install\/packages\/lib\/python3.10\/site-packages\/starlette\/routing.py\", line 72, in app\n    response = await func(request)\n  File \"\/layers\/paketo-buildpacks_pip-install\/packages\/lib\/python3.10\/site-packages\/fastapi\/routing.py\", line 299, in app\n    raise e\n  File \"\/layers\/paketo-buildpacks_pip-install\/packages\/lib\/python3.10\/site-packages\/fastapi\/routing.py\", line 294, in app\n    raw_response = await run_endpoint_function(\n  File \"\/layers\/paketo-buildpacks_pip-install\/packages\/lib\/python3.10\/site-packages\/fastapi\/routing.py\", line 193, in run_endpoint_function\n    return await run_in_threadpool(dependant.call, **values)\n  File \"\/layers\/paketo-buildpacks_pip-install\/packages\/lib\/python3.10\/site-packages\/starlette\/concurrency.py\", line 40, in run_in_threadpool\n    return await anyio.to_thread.run_sync(func, *args)\n  File \"\/layers\/paketo-buildpacks_pip-install\/packages\/lib\/python3.10\/site-packages\/anyio\/to_thread.py\", line 56, in run_sync\n    return await get_async_backend().run_sync_in_worker_thread(\n  File \"\/layers\/paketo-buildpacks_pip-install\/packages\/lib\/python3.10\/site-packages\/anyio\/_backends\/_asyncio.py\", line 2134, in run_sync_in_worker_thread\n    return await future\n  File \"\/layers\/paketo-buildpacks_pip-install\/packages\/lib\/python3.10\/site-packages\/anyio\/_backends\/_asyncio.py\", line 851, in run\n    result = context.run(func, *args)\n  File \"\/workspace\/app\/routes\/user.py\", line 19, in get_token\n    if validate_user(user):\n  File \"\/workspace\/app\/func\/user.py\", line 26, in validate_user\n    r1=db.query(user_model).where(user_model.uuid_user==id_user).one()\n  File \"\/layers\/paketo-buildpacks_pip-install\/packages\/lib\/python3.10\/site-packages\/sqlalchemy\/orm\/query.py\", line 2798, in one\n    return self._iter().one()  # type: ignore\n  File \"\/layers\/paketo-buildpacks_pip-install\/packages\/lib\/python3.10\/site-packages\/sqlalchemy\/orm\/query.py\", line 2847, in _iter\n    result: Union[ScalarResult[_T], Result[_T]] = self.session.execute(\n  File \"\/layers\/paketo-buildpacks_pip-install\/packages\/lib\/python3.10\/site-packages\/sqlalchemy\/orm\/session.py\", line 2308, in execute\n    return self._execute_internal(\n  File \"\/layers\/paketo-buildpacks_pip-install\/packages\/lib\/python3.10\/site-packages\/sqlalchemy\/orm\/session.py\", line 2190, in _execute_internal\n    result: Result[Any] = compile_state_cls.orm_execute_statement(\n  File \"\/layers\/paketo-buildpacks_pip-install\/packages\/lib\/python3.10\/site-packages\/sqlalchemy\/orm\/context.py\", line 293, in orm_execute_statement\n    result = conn.execute(\n  File \"\/layers\/paketo-buildpacks_pip-install\/packages\/lib\/python3.10\/site-packages\/sqlalchemy\/engine\/base.py\", line 1416, in execute\n    return meth(\n  File \"\/layers\/paketo-buildpacks_pip-install\/packages\/lib\/python3.10\/site-packages\/sqlalchemy\/sql\/elements.py\", line 517, in _execute_on_connection\n    return connection._execute_clauseelement(\n  File \"\/layers\/paketo-buildpacks_pip-install\/packages\/lib\/python3.10\/site-packages\/sqlalchemy\/engine\/base.py\", line 1639, in _execute_clauseelement\n    ret = self._execute_context(\n  File \"\/layers\/paketo-buildpacks_pip-install\/packages\/lib\/python3.10\/site-packages\/sqlalchemy\/engine\/base.py\", line 1848, in _execute_context\n    return self._exec_single_context(\n  File \"\/layers\/paketo-buildpacks_pip-install\/packages\/lib\/python3.10\/site-packages\/sqlalchemy\/engine\/base.py\", line 1988, in _exec_single_context\n    self._handle_dbapi_exception(\n  File \"\/layers\/paketo-buildpacks_pip-install\/packages\/lib\/python3.10\/site-packages\/sqlalchemy\/engine\/base.py\", line 2344, in _handle_dbapi_exception\n    raise sqlalchemy_exception.with_traceback(exc_info[2]) from e\n  File \"\/layers\/paketo-buildpacks_pip-install\/packages\/lib\/python3.10\/site-packages\/sqlalchemy\/engine\/base.py\", line 1969, in _exec_single_context\n    self.dialect.do_execute(\n  File \"\/layers\/paketo-buildpacks_pip-install\/packages\/lib\/python3.10\/site-packages\/sqlalchemy\/engine\/default.py\", line 922, in do_execute\n    cursor.execute(statement, parameters)\n  File \"\/layers\/paketo-buildpacks_pip-install\/packages\/lib\/python3.10\/site-packages\/pymysql\/cursors.py\", line 153, in execute\n    result = self._query(query)\n  File \"\/layers\/paketo-buildpacks_pip-install\/packages\/lib\/python3.10\/site-packages\/pymysql\/cursors.py\", line 322, in _query\n    conn.query(q)\n  File \"\/layers\/paketo-buildpacks_pip-install\/packages\/lib\/python3.10\/site-packages\/pymysql\/connections.py\", line 558, in query\n    self._affected_rows = self._read_query_result(unbuffered=unbuffered)\n  File \"\/layers\/paketo-buildpacks_pip-install\/packages\/lib\/python3.10\/site-packages\/pymysql\/connections.py\", line 822, in _read_query_result\n    result.read()\n  File \"\/layers\/paketo-buildpacks_pip-install\/packages\/lib\/python3.10\/site-packages\/pymysql\/connections.py\", line 1200, in read\n    first_packet = self.connection._read_packet()\n  File \"\/layers\/paketo-buildpacks_pip-install\/packages\/lib\/python3.10\/site-packages\/pymysql\/connections.py\", line 739, in _read_packet\n    packet_header = self._read_bytes(4)\n  File \"\/layers\/paketo-buildpacks_pip-install\/packages\/lib\/python3.10\/site-packages\/pymysql\/connections.py\", line 795, in _read_bytes\n    raise err.OperationalError(\nsqlalchemy.exc.OperationalError: (pymysql.err.OperationalError) (2013, 'Lost connection to MySQL server during query')\n[SQL: SELECT users.uuid_user AS users_uuid_user, users.user AS users_user, users.password AS users_password, users.rol_uuid AS users_rol_uuid, users.is_active AS users_is_active, users.last_connection AS users_last_connection, users.created_at AS users_created_at, users.updated_at AS users_updated_at \nFROM users \nWHERE users.uuid_user = %(uuid_user_1)s]\n[parameters: {'uuid_user_1': 'a0ce19ba-1824-478e-800b-8d8ae78cc608'}]\n(Background on this error at: https:\/\/sqlalche.me\/e\/20\/e3q8)\n\nsrc\/test\/java\/payments\/post\/..\/..\/user\/token\/users-token-post.feature:9\nsrc\/test\/java\/payments\/post\/create_payments-post.feature:5\n","callResults":[{"failedCount":1,"prefixedPath":"src\/test\/java\/payments\/post\/..\/..\/user\/token\/users-token-post.feature","packageQualifiedName":"src.test.java.payments.post.user.token.users-token-post","loopIndex":-1,"relativePath":"src\/test\/java\/payments\/post\/..\/..\/user\/token\/users-token-post.feature","scenarioResults":[{"sectionIndex":0,"stepResults":[{"result":{"nanos":2303400,"millis":2.3034,"status":"passed"},"step":{"line":6,"prefix":"Given","index":0,"text":"url \"https:\/\/funcoeback-dev-ceqh.3.us-1.fl0.io\/users\/token\/\""}},{"result":{"nanos":398089300,"millis":398.0893,"status":"passed"},"step":{"line":7,"prefix":"And","index":1,"text":"request {\"user\": \"ruben1\", \"password\": \"ruben123\"}"}},{"result":{"nanos":1804092500,"millis":1804.0925,"status":"passed"},"step":{"line":8,"prefix":"When","index":2,"text":"method post"},"stepLog":"22:15:28.619 request:\n1 > POST https:\/\/funcoeback-dev-ceqh.3.us-1.fl0.io\/users\/token\/\n1 > Content-Type: application\/json; charset=UTF-8\n1 > Content-Length: 39\n1 > Host: funcoeback-dev-ceqh.3.us-1.fl0.io\n1 > Connection: Keep-Alive\n1 > User-Agent: Apache-HttpClient\/4.5.13 (Java\/21.0.2)\n1 > Accept-Encoding: gzip,deflate\n{\"user\":\"ruben1\",\"password\":\"ruben123\"}\n\n22:15:29.864 response time in milliseconds: 1243\n1 < 500\n1 < date: Tue, 05 Mar 2024 03:15:29 GMT\n1 < server: envoy\n1 < content-length: 9353\n1 < content-type: text\/plain; charset=utf-8\n1 < x-envoy-upstream-service-time: 245\nTraceback (most recent call last):\n  File \"\/layers\/paketo-buildpacks_pip-install\/packages\/lib\/python3.10\/site-packages\/sqlalchemy\/engine\/base.py\", line 1969, in _exec_single_context\n    self.dialect.do_execute(\n  File \"\/layers\/paketo-buildpacks_pip-install\/packages\/lib\/python3.10\/site-packages\/sqlalchemy\/engine\/default.py\", line 922, in do_execute\n    cursor.execute(statement, parameters)\n  File \"\/layers\/paketo-buildpacks_pip-install\/packages\/lib\/python3.10\/site-packages\/pymysql\/cursors.py\", line 153, in execute\n    result = self._query(query)\n  File \"\/layers\/paketo-buildpacks_pip-install\/packages\/lib\/python3.10\/site-packages\/pymysql\/cursors.py\", line 322, in _query\n    conn.query(q)\n  File \"\/layers\/paketo-buildpacks_pip-install\/packages\/lib\/python3.10\/site-packages\/pymysql\/connections.py\", line 558, in query\n    self._affected_rows = self._read_query_result(unbuffered=unbuffered)\n  File \"\/layers\/paketo-buildpacks_pip-install\/packages\/lib\/python3.10\/site-packages\/pymysql\/connections.py\", line 822, in _read_query_result\n    result.read()\n  File \"\/layers\/paketo-buildpacks_pip-install\/packages\/lib\/python3.10\/site-packages\/pymysql\/connections.py\", line 1200, in read\n    first_packet = self.connection._read_packet()\n  File \"\/layers\/paketo-buildpacks_pip-install\/packages\/lib\/python3.10\/site-packages\/pymysql\/connections.py\", line 739, in _read_packet\n    packet_header = self._read_bytes(4)\n  File \"\/layers\/paketo-buildpacks_pip-install\/packages\/lib\/python3.10\/site-packages\/pymysql\/connections.py\", line 795, in _read_bytes\n    raise err.OperationalError(\npymysql.err.OperationalError: (2013, 'Lost connection to MySQL server during query')\n\nThe above exception was the direct cause of the following exception:\n\nTraceback (most recent call last):\n  File \"\/layers\/paketo-buildpacks_pip-install\/packages\/lib\/python3.10\/site-packages\/starlette\/middleware\/errors.py\", line 164, in __call__\n    await self.app(scope, receive, _send)\n  File \"\/layers\/paketo-buildpacks_pip-install\/packages\/lib\/python3.10\/site-packages\/starlette\/middleware\/exceptions.py\", line 62, in __call__\n    await wrap_app_handling_exceptions(self.app, conn)(scope, receive, send)\n  File \"\/layers\/paketo-buildpacks_pip-install\/packages\/lib\/python3.10\/site-packages\/starlette\/_exception_handler.py\", line 64, in wrapped_app\n    raise exc\n  File \"\/layers\/paketo-buildpacks_pip-install\/packages\/lib\/python3.10\/site-packages\/starlette\/_exception_handler.py\", line 53, in wrapped_app\n    await app(scope, receive, sender)\n  File \"\/layers\/paketo-buildpacks_pip-install\/packages\/lib\/python3.10\/site-packages\/starlette\/routing.py\", line 762, in __call__\n    await self.middleware_stack(scope, receive, send)\n  File \"\/layers\/paketo-buildpacks_pip-install\/packages\/lib\/python3.10\/site-packages\/starlette\/routing.py\", line 782, in app\n    await route.handle(scope, receive, send)\n  File \"\/layers\/paketo-buildpacks_pip-install\/packages\/lib\/python3.10\/site-packages\/starlette\/routing.py\", line 297, in handle\n    await self.app(scope, receive, send)\n  File \"\/layers\/paketo-buildpacks_pip-install\/packages\/lib\/python3.10\/site-packages\/starlette\/routing.py\", line 77, in app\n    await wrap_app_handling_exceptions(app, request)(scope, receive, send)\n  File \"\/layers\/paketo-buildpacks_pip-install\/packages\/lib\/python3.10\/site-packages\/starlette\/_exception_handler.py\", line 64, in wrapped_app\n    raise exc\n  File \"\/layers\/paketo-buildpacks_pip-install\/packages\/lib\/python3.10\/site-packages\/starlette\/_exception_handler.py\", line 53, in wrapped_app\n    await app(scope, receive, sender)\n  File \"\/layers\/paketo-buildpacks_pip-install\/packages\/lib\/python3.10\/site-packages\/starlette\/routing.py\", line 72, in app\n    response = await func(request)\n  File \"\/layers\/paketo-buildpacks_pip-install\/packages\/lib\/python3.10\/site-packages\/fastapi\/routing.py\", line 299, in app\n    raise e\n  File \"\/layers\/paketo-buildpacks_pip-install\/packages\/lib\/python3.10\/site-packages\/fastapi\/routing.py\", line 294, in app\n    raw_response = await run_endpoint_function(\n  File \"\/layers\/paketo-buildpacks_pip-install\/packages\/lib\/python3.10\/site-packages\/fastapi\/routing.py\", line 193, in run_endpoint_function\n    return await run_in_threadpool(dependant.call, **values)\n  File \"\/layers\/paketo-buildpacks_pip-install\/packages\/lib\/python3.10\/site-packages\/starlette\/concurrency.py\", line 40, in run_in_threadpool\n    return await anyio.to_thread.run_sync(func, *args)\n  File \"\/layers\/paketo-buildpacks_pip-install\/packages\/lib\/python3.10\/site-packages\/anyio\/to_thread.py\", line 56, in run_sync\n    return await get_async_backend().run_sync_in_worker_thread(\n  File \"\/layers\/paketo-buildpacks_pip-install\/packages\/lib\/python3.10\/site-packages\/anyio\/_backends\/_asyncio.py\", line 2134, in run_sync_in_worker_thread\n    return await future\n  File \"\/layers\/paketo-buildpacks_pip-install\/packages\/lib\/python3.10\/site-packages\/anyio\/_backends\/_asyncio.py\", line 851, in run\n    result = context.run(func, *args)\n  File \"\/workspace\/app\/routes\/user.py\", line 19, in get_token\n    if validate_user(user):\n  File \"\/workspace\/app\/func\/user.py\", line 26, in validate_user\n    r1=db.query(user_model).where(user_model.uuid_user==id_user).one()\n  File \"\/layers\/paketo-buildpacks_pip-install\/packages\/lib\/python3.10\/site-packages\/sqlalchemy\/orm\/query.py\", line 2798, in one\n    return self._iter().one()  # type: ignore\n  File \"\/layers\/paketo-buildpacks_pip-install\/packages\/lib\/python3.10\/site-packages\/sqlalchemy\/orm\/query.py\", line 2847, in _iter\n    result: Union[ScalarResult[_T], Result[_T]] = self.session.execute(\n  File \"\/layers\/paketo-buildpacks_pip-install\/packages\/lib\/python3.10\/site-packages\/sqlalchemy\/orm\/session.py\", line 2308, in execute\n    return self._execute_internal(\n  File \"\/layers\/paketo-buildpacks_pip-install\/packages\/lib\/python3.10\/site-packages\/sqlalchemy\/orm\/session.py\", line 2190, in _execute_internal\n    result: Result[Any] = compile_state_cls.orm_execute_statement(\n  File \"\/layers\/paketo-buildpacks_pip-install\/packages\/lib\/python3.10\/site-packages\/sqlalchemy\/orm\/context.py\", line 293, in orm_execute_statement\n    result = conn.execute(\n  File \"\/layers\/paketo-buildpacks_pip-install\/packages\/lib\/python3.10\/site-packages\/sqlalchemy\/engine\/base.py\", line 1416, in execute\n    return meth(\n  File \"\/layers\/paketo-buildpacks_pip-install\/packages\/lib\/python3.10\/site-packages\/sqlalchemy\/sql\/elements.py\", line 517, in _execute_on_connection\n    return connection._execute_clauseelement(\n  File \"\/layers\/paketo-buildpacks_pip-install\/packages\/lib\/python3.10\/site-packages\/sqlalchemy\/engine\/base.py\", line 1639, in _execute_clauseelement\n    ret = self._execute_context(\n  File \"\/layers\/paketo-buildpacks_pip-install\/packages\/lib\/python3.10\/site-packages\/sqlalchemy\/engine\/base.py\", line 1848, in _execute_context\n    return self._exec_single_context(\n  File \"\/layers\/paketo-buildpacks_pip-install\/packages\/lib\/python3.10\/site-packages\/sqlalchemy\/engine\/base.py\", line 1988, in _exec_single_context\n    self._handle_dbapi_exception(\n  File \"\/layers\/paketo-buildpacks_pip-install\/packages\/lib\/python3.10\/site-packages\/sqlalchemy\/engine\/base.py\", line 2344, in _handle_dbapi_exception\n    raise sqlalchemy_exception.with_traceback(exc_info[2]) from e\n  File \"\/layers\/paketo-buildpacks_pip-install\/packages\/lib\/python3.10\/site-packages\/sqlalchemy\/engine\/base.py\", line 1969, in _exec_single_context\n    self.dialect.do_execute(\n  File \"\/layers\/paketo-buildpacks_pip-install\/packages\/lib\/python3.10\/site-packages\/sqlalchemy\/engine\/default.py\", line 922, in do_execute\n    cursor.execute(statement, parameters)\n  File \"\/layers\/paketo-buildpacks_pip-install\/packages\/lib\/python3.10\/site-packages\/pymysql\/cursors.py\", line 153, in execute\n    result = self._query(query)\n  File \"\/layers\/paketo-buildpacks_pip-install\/packages\/lib\/python3.10\/site-packages\/pymysql\/cursors.py\", line 322, in _query\n    conn.query(q)\n  File \"\/layers\/paketo-buildpacks_pip-install\/packages\/lib\/python3.10\/site-packages\/pymysql\/connections.py\", line 558, in query\n    self._affected_rows = self._read_query_result(unbuffered=unbuffered)\n  File \"\/layers\/paketo-buildpacks_pip-install\/packages\/lib\/python3.10\/site-packages\/pymysql\/connections.py\", line 822, in _read_query_result\n    result.read()\n  File \"\/layers\/paketo-buildpacks_pip-install\/packages\/lib\/python3.10\/site-packages\/pymysql\/connections.py\", line 1200, in read\n    first_packet = self.connection._read_packet()\n  File \"\/layers\/paketo-buildpacks_pip-install\/packages\/lib\/python3.10\/site-packages\/pymysql\/connections.py\", line 739, in _read_packet\n    packet_header = self._read_bytes(4)\n  File \"\/layers\/paketo-buildpacks_pip-install\/packages\/lib\/python3.10\/site-packages\/pymysql\/connections.py\", line 795, in _read_bytes\n    raise err.OperationalError(\nsqlalchemy.exc.OperationalError: (pymysql.err.OperationalError) (2013, 'Lost connection to MySQL server during query')\n[SQL: SELECT users.uuid_user AS users_uuid_user, users.user AS users_user, users.password AS users_password, users.rol_uuid AS users_rol_uuid, users.is_active AS users_is_active, users.last_connection AS users_last_connection, users.created_at AS users_created_at, users.updated_at AS users_updated_at \nFROM users \nWHERE users.uuid_user = %(uuid_user_1)s]\n[parameters: {'uuid_user_1': 'a0ce19ba-1824-478e-800b-8d8ae78cc608'}]\n(Background on this error at: https:\/\/sqlalche.me\/e\/20\/e3q8)\n\n\n"},{"result":{"nanos":34715800,"errorMessage":"status code was: 500, expected: 200, response time in milliseconds: 1243, url: https:\/\/funcoeback-dev-ceqh.3.us-1.fl0.io\/users\/token\/, response: \nTraceback (most recent call last):\n  File \"\/layers\/paketo-buildpacks_pip-install\/packages\/lib\/python3.10\/site-packages\/sqlalchemy\/engine\/base.py\", line 1969, in _exec_single_context\n    self.dialect.do_execute(\n  File \"\/layers\/paketo-buildpacks_pip-install\/packages\/lib\/python3.10\/site-packages\/sqlalchemy\/engine\/default.py\", line 922, in do_execute\n    cursor.execute(statement, parameters)\n  File \"\/layers\/paketo-buildpacks_pip-install\/packages\/lib\/python3.10\/site-packages\/pymysql\/cursors.py\", line 153, in execute\n    result = self._query(query)\n  File \"\/layers\/paketo-buildpacks_pip-install\/packages\/lib\/python3.10\/site-packages\/pymysql\/cursors.py\", line 322, in _query\n    conn.query(q)\n  File \"\/layers\/paketo-buildpacks_pip-install\/packages\/lib\/python3.10\/site-packages\/pymysql\/connections.py\", line 558, in query\n    self._affected_rows = self._read_query_result(unbuffered=unbuffered)\n  File \"\/layers\/paketo-buildpacks_pip-install\/packages\/lib\/python3.10\/site-packages\/pymysql\/connections.py\", line 822, in _read_query_result\n    result.read()\n  File \"\/layers\/paketo-buildpacks_pip-install\/packages\/lib\/python3.10\/site-packages\/pymysql\/connections.py\", line 1200, in read\n    first_packet = self.connection._read_packet()\n  File \"\/layers\/paketo-buildpacks_pip-install\/packages\/lib\/python3.10\/site-packages\/pymysql\/connections.py\", line 739, in _read_packet\n    packet_header = self._read_bytes(4)\n  File \"\/layers\/paketo-buildpacks_pip-install\/packages\/lib\/python3.10\/site-packages\/pymysql\/connections.py\", line 795, in _read_bytes\n    raise err.OperationalError(\npymysql.err.OperationalError: (2013, 'Lost connection to MySQL server during query')\n\nThe above exception was the direct cause of the following exception:\n\nTraceback (most recent call last):\n  File \"\/layers\/paketo-buildpacks_pip-install\/packages\/lib\/python3.10\/site-packages\/starlette\/middleware\/errors.py\", line 164, in __call__\n    await self.app(scope, receive, _send)\n  File \"\/layers\/paketo-buildpacks_pip-install\/packages\/lib\/python3.10\/site-packages\/starlette\/middleware\/exceptions.py\", line 62, in __call__\n    await wrap_app_handling_exceptions(self.app, conn)(scope, receive, send)\n  File \"\/layers\/paketo-buildpacks_pip-install\/packages\/lib\/python3.10\/site-packages\/starlette\/_exception_handler.py\", line 64, in wrapped_app\n    raise exc\n  File \"\/layers\/paketo-buildpacks_pip-install\/packages\/lib\/python3.10\/site-packages\/starlette\/_exception_handler.py\", line 53, in wrapped_app\n    await app(scope, receive, sender)\n  File \"\/layers\/paketo-buildpacks_pip-install\/packages\/lib\/python3.10\/site-packages\/starlette\/routing.py\", line 762, in __call__\n    await self.middleware_stack(scope, receive, send)\n  File \"\/layers\/paketo-buildpacks_pip-install\/packages\/lib\/python3.10\/site-packages\/starlette\/routing.py\", line 782, in app\n    await route.handle(scope, receive, send)\n  File \"\/layers\/paketo-buildpacks_pip-install\/packages\/lib\/python3.10\/site-packages\/starlette\/routing.py\", line 297, in handle\n    await self.app(scope, receive, send)\n  File \"\/layers\/paketo-buildpacks_pip-install\/packages\/lib\/python3.10\/site-packages\/starlette\/routing.py\", line 77, in app\n    await wrap_app_handling_exceptions(app, request)(scope, receive, send)\n  File \"\/layers\/paketo-buildpacks_pip-install\/packages\/lib\/python3.10\/site-packages\/starlette\/_exception_handler.py\", line 64, in wrapped_app\n    raise exc\n  File \"\/layers\/paketo-buildpacks_pip-install\/packages\/lib\/python3.10\/site-packages\/starlette\/_exception_handler.py\", line 53, in wrapped_app\n    await app(scope, receive, sender)\n  File \"\/layers\/paketo-buildpacks_pip-install\/packages\/lib\/python3.10\/site-packages\/starlette\/routing.py\", line 72, in app\n    response = await func(request)\n  File \"\/layers\/paketo-buildpacks_pip-install\/packages\/lib\/python3.10\/site-packages\/fastapi\/routing.py\", line 299, in app\n    raise e\n  File \"\/layers\/paketo-buildpacks_pip-install\/packages\/lib\/python3.10\/site-packages\/fastapi\/routing.py\", line 294, in app\n    raw_response = await run_endpoint_function(\n  File \"\/layers\/paketo-buildpacks_pip-install\/packages\/lib\/python3.10\/site-packages\/fastapi\/routing.py\", line 193, in run_endpoint_function\n    return await run_in_threadpool(dependant.call, **values)\n  File \"\/layers\/paketo-buildpacks_pip-install\/packages\/lib\/python3.10\/site-packages\/starlette\/concurrency.py\", line 40, in run_in_threadpool\n    return await anyio.to_thread.run_sync(func, *args)\n  File \"\/layers\/paketo-buildpacks_pip-install\/packages\/lib\/python3.10\/site-packages\/anyio\/to_thread.py\", line 56, in run_sync\n    return await get_async_backend().run_sync_in_worker_thread(\n  File \"\/layers\/paketo-buildpacks_pip-install\/packages\/lib\/python3.10\/site-packages\/anyio\/_backends\/_asyncio.py\", line 2134, in run_sync_in_worker_thread\n    return await future\n  File \"\/layers\/paketo-buildpacks_pip-install\/packages\/lib\/python3.10\/site-packages\/anyio\/_backends\/_asyncio.py\", line 851, in run\n    result = context.run(func, *args)\n  File \"\/workspace\/app\/routes\/user.py\", line 19, in get_token\n    if validate_user(user):\n  File \"\/workspace\/app\/func\/user.py\", line 26, in validate_user\n    r1=db.query(user_model).where(user_model.uuid_user==id_user).one()\n  File \"\/layers\/paketo-buildpacks_pip-install\/packages\/lib\/python3.10\/site-packages\/sqlalchemy\/orm\/query.py\", line 2798, in one\n    return self._iter().one()  # type: ignore\n  File \"\/layers\/paketo-buildpacks_pip-install\/packages\/lib\/python3.10\/site-packages\/sqlalchemy\/orm\/query.py\", line 2847, in _iter\n    result: Union[ScalarResult[_T], Result[_T]] = self.session.execute(\n  File \"\/layers\/paketo-buildpacks_pip-install\/packages\/lib\/python3.10\/site-packages\/sqlalchemy\/orm\/session.py\", line 2308, in execute\n    return self._execute_internal(\n  File \"\/layers\/paketo-buildpacks_pip-install\/packages\/lib\/python3.10\/site-packages\/sqlalchemy\/orm\/session.py\", line 2190, in _execute_internal\n    result: Result[Any] = compile_state_cls.orm_execute_statement(\n  File \"\/layers\/paketo-buildpacks_pip-install\/packages\/lib\/python3.10\/site-packages\/sqlalchemy\/orm\/context.py\", line 293, in orm_execute_statement\n    result = conn.execute(\n  File \"\/layers\/paketo-buildpacks_pip-install\/packages\/lib\/python3.10\/site-packages\/sqlalchemy\/engine\/base.py\", line 1416, in execute\n    return meth(\n  File \"\/layers\/paketo-buildpacks_pip-install\/packages\/lib\/python3.10\/site-packages\/sqlalchemy\/sql\/elements.py\", line 517, in _execute_on_connection\n    return connection._execute_clauseelement(\n  File \"\/layers\/paketo-buildpacks_pip-install\/packages\/lib\/python3.10\/site-packages\/sqlalchemy\/engine\/base.py\", line 1639, in _execute_clauseelement\n    ret = self._execute_context(\n  File \"\/layers\/paketo-buildpacks_pip-install\/packages\/lib\/python3.10\/site-packages\/sqlalchemy\/engine\/base.py\", line 1848, in _execute_context\n    return self._exec_single_context(\n  File \"\/layers\/paketo-buildpacks_pip-install\/packages\/lib\/python3.10\/site-packages\/sqlalchemy\/engine\/base.py\", line 1988, in _exec_single_context\n    self._handle_dbapi_exception(\n  File \"\/layers\/paketo-buildpacks_pip-install\/packages\/lib\/python3.10\/site-packages\/sqlalchemy\/engine\/base.py\", line 2344, in _handle_dbapi_exception\n    raise sqlalchemy_exception.with_traceback(exc_info[2]) from e\n  File \"\/layers\/paketo-buildpacks_pip-install\/packages\/lib\/python3.10\/site-packages\/sqlalchemy\/engine\/base.py\", line 1969, in _exec_single_context\n    self.dialect.do_execute(\n  File \"\/layers\/paketo-buildpacks_pip-install\/packages\/lib\/python3.10\/site-packages\/sqlalchemy\/engine\/default.py\", line 922, in do_execute\n    cursor.execute(statement, parameters)\n  File \"\/layers\/paketo-buildpacks_pip-install\/packages\/lib\/python3.10\/site-packages\/pymysql\/cursors.py\", line 153, in execute\n    result = self._query(query)\n  File \"\/layers\/paketo-buildpacks_pip-install\/packages\/lib\/python3.10\/site-packages\/pymysql\/cursors.py\", line 322, in _query\n    conn.query(q)\n  File \"\/layers\/paketo-buildpacks_pip-install\/packages\/lib\/python3.10\/site-packages\/pymysql\/connections.py\", line 558, in query\n    self._affected_rows = self._read_query_result(unbuffered=unbuffered)\n  File \"\/layers\/paketo-buildpacks_pip-install\/packages\/lib\/python3.10\/site-packages\/pymysql\/connections.py\", line 822, in _read_query_result\n    result.read()\n  File \"\/layers\/paketo-buildpacks_pip-install\/packages\/lib\/python3.10\/site-packages\/pymysql\/connections.py\", line 1200, in read\n    first_packet = self.connection._read_packet()\n  File \"\/layers\/paketo-buildpacks_pip-install\/packages\/lib\/python3.10\/site-packages\/pymysql\/connections.py\", line 739, in _read_packet\n    packet_header = self._read_bytes(4)\n  File \"\/layers\/paketo-buildpacks_pip-install\/packages\/lib\/python3.10\/site-packages\/pymysql\/connections.py\", line 795, in _read_bytes\n    raise err.OperationalError(\nsqlalchemy.exc.OperationalError: (pymysql.err.OperationalError) (2013, 'Lost connection to MySQL server during query')\n[SQL: SELECT users.uuid_user AS users_uuid_user, users.user AS users_user, users.password AS users_password, users.rol_uuid AS users_rol_uuid, users.is_active AS users_is_active, users.last_connection AS users_last_connection, users.created_at AS users_created_at, users.updated_at AS users_updated_at \nFROM users \nWHERE users.uuid_user = %(uuid_user_1)s]\n[parameters: {'uuid_user_1': 'a0ce19ba-1824-478e-800b-8d8ae78cc608'}]\n(Background on this error at: https:\/\/sqlalche.me\/e\/20\/e3q8)\n\nsrc\/test\/java\/payments\/post\/..\/..\/user\/token\/users-token-post.feature:9","millis":34.7158,"status":"failed"},"step":{"line":9,"prefix":"Then","index":3,"text":"status 200"},"stepLog":"22:15:29.902 src\/test\/java\/payments\/post\/..\/..\/user\/token\/users-token-post.feature:9\nThen status 200\nstatus code was: 500, expected: 200, response time in milliseconds: 1243, url: https:\/\/funcoeback-dev-ceqh.3.us-1.fl0.io\/users\/token\/, response: \nTraceback (most recent call last):\n  File \"\/layers\/paketo-buildpacks_pip-install\/packages\/lib\/python3.10\/site-packages\/sqlalchemy\/engine\/base.py\", line 1969, in _exec_single_context\n    self.dialect.do_execute(\n  File \"\/layers\/paketo-buildpacks_pip-install\/packages\/lib\/python3.10\/site-packages\/sqlalchemy\/engine\/default.py\", line 922, in do_execute\n    cursor.execute(statement, parameters)\n  File \"\/layers\/paketo-buildpacks_pip-install\/packages\/lib\/python3.10\/site-packages\/pymysql\/cursors.py\", line 153, in execute\n    result = self._query(query)\n  File \"\/layers\/paketo-buildpacks_pip-install\/packages\/lib\/python3.10\/site-packages\/pymysql\/cursors.py\", line 322, in _query\n    conn.query(q)\n  File \"\/layers\/paketo-buildpacks_pip-install\/packages\/lib\/python3.10\/site-packages\/pymysql\/connections.py\", line 558, in query\n    self._affected_rows = self._read_query_result(unbuffered=unbuffered)\n  File \"\/layers\/paketo-buildpacks_pip-install\/packages\/lib\/python3.10\/site-packages\/pymysql\/connections.py\", line 822, in _read_query_result\n    result.read()\n  File \"\/layers\/paketo-buildpacks_pip-install\/packages\/lib\/python3.10\/site-packages\/pymysql\/connections.py\", line 1200, in read\n    first_packet = self.connection._read_packet()\n  File \"\/layers\/paketo-buildpacks_pip-install\/packages\/lib\/python3.10\/site-packages\/pymysql\/connections.py\", line 739, in _read_packet\n    packet_header = self._read_bytes(4)\n  File \"\/layers\/paketo-buildpacks_pip-install\/packages\/lib\/python3.10\/site-packages\/pymysql\/connections.py\", line 795, in _read_bytes\n    raise err.OperationalError(\npymysql.err.OperationalError: (2013, 'Lost connection to MySQL server during query')\n\nThe above exception was the direct cause of the following exception:\n\nTraceback (most recent call last):\n  File \"\/layers\/paketo-buildpacks_pip-install\/packages\/lib\/python3.10\/site-packages\/starlette\/middleware\/errors.py\", line 164, in __call__\n    await self.app(scope, receive, _send)\n  File \"\/layers\/paketo-buildpacks_pip-install\/packages\/lib\/python3.10\/site-packages\/starlette\/middleware\/exceptions.py\", line 62, in __call__\n    await wrap_app_handling_exceptions(self.app, conn)(scope, receive, send)\n  File \"\/layers\/paketo-buildpacks_pip-install\/packages\/lib\/python3.10\/site-packages\/starlette\/_exception_handler.py\", line 64, in wrapped_app\n    raise exc\n  File \"\/layers\/paketo-buildpacks_pip-install\/packages\/lib\/python3.10\/site-packages\/starlette\/_exception_handler.py\", line 53, in wrapped_app\n    await app(scope, receive, sender)\n  File \"\/layers\/paketo-buildpacks_pip-install\/packages\/lib\/python3.10\/site-packages\/starlette\/routing.py\", line 762, in __call__\n    await self.middleware_stack(scope, receive, send)\n  File \"\/layers\/paketo-buildpacks_pip-install\/packages\/lib\/python3.10\/site-packages\/starlette\/routing.py\", line 782, in app\n    await route.handle(scope, receive, send)\n  File \"\/layers\/paketo-buildpacks_pip-install\/packages\/lib\/python3.10\/site-packages\/starlette\/routing.py\", line 297, in handle\n    await self.app(scope, receive, send)\n  File \"\/layers\/paketo-buildpacks_pip-install\/packages\/lib\/python3.10\/site-packages\/starlette\/routing.py\", line 77, in app\n    await wrap_app_handling_exceptions(app, request)(scope, receive, send)\n  File \"\/layers\/paketo-buildpacks_pip-install\/packages\/lib\/python3.10\/site-packages\/starlette\/_exception_handler.py\", line 64, in wrapped_app\n    raise exc\n  File \"\/layers\/paketo-buildpacks_pip-install\/packages\/lib\/python3.10\/site-packages\/starlette\/_exception_handler.py\", line 53, in wrapped_app\n    await app(scope, receive, sender)\n  File \"\/layers\/paketo-buildpacks_pip-install\/packages\/lib\/python3.10\/site-packages\/starlette\/routing.py\", line 72, in app\n    response = await func(request)\n  File \"\/layers\/paketo-buildpacks_pip-install\/packages\/lib\/python3.10\/site-packages\/fastapi\/routing.py\", line 299, in app\n    raise e\n  File \"\/layers\/paketo-buildpacks_pip-install\/packages\/lib\/python3.10\/site-packages\/fastapi\/routing.py\", line 294, in app\n    raw_response = await run_endpoint_function(\n  File \"\/layers\/paketo-buildpacks_pip-install\/packages\/lib\/python3.10\/site-packages\/fastapi\/routing.py\", line 193, in run_endpoint_function\n    return await run_in_threadpool(dependant.call, **values)\n  File \"\/layers\/paketo-buildpacks_pip-install\/packages\/lib\/python3.10\/site-packages\/starlette\/concurrency.py\", line 40, in run_in_threadpool\n    return await anyio.to_thread.run_sync(func, *args)\n  File \"\/layers\/paketo-buildpacks_pip-install\/packages\/lib\/python3.10\/site-packages\/anyio\/to_thread.py\", line 56, in run_sync\n    return await get_async_backend().run_sync_in_worker_thread(\n  File \"\/layers\/paketo-buildpacks_pip-install\/packages\/lib\/python3.10\/site-packages\/anyio\/_backends\/_asyncio.py\", line 2134, in run_sync_in_worker_thread\n    return await future\n  File \"\/layers\/paketo-buildpacks_pip-install\/packages\/lib\/python3.10\/site-packages\/anyio\/_backends\/_asyncio.py\", line 851, in run\n    result = context.run(func, *args)\n  File \"\/workspace\/app\/routes\/user.py\", line 19, in get_token\n    if validate_user(user):\n  File \"\/workspace\/app\/func\/user.py\", line 26, in validate_user\n    r1=db.query(user_model).where(user_model.uuid_user==id_user).one()\n  File \"\/layers\/paketo-buildpacks_pip-install\/packages\/lib\/python3.10\/site-packages\/sqlalchemy\/orm\/query.py\", line 2798, in one\n    return self._iter().one()  # type: ignore\n  File \"\/layers\/paketo-buildpacks_pip-install\/packages\/lib\/python3.10\/site-packages\/sqlalchemy\/orm\/query.py\", line 2847, in _iter\n    result: Union[ScalarResult[_T], Result[_T]] = self.session.execute(\n  File \"\/layers\/paketo-buildpacks_pip-install\/packages\/lib\/python3.10\/site-packages\/sqlalchemy\/orm\/session.py\", line 2308, in execute\n    return self._execute_internal(\n  File \"\/layers\/paketo-buildpacks_pip-install\/packages\/lib\/python3.10\/site-packages\/sqlalchemy\/orm\/session.py\", line 2190, in _execute_internal\n    result: Result[Any] = compile_state_cls.orm_execute_statement(\n  File \"\/layers\/paketo-buildpacks_pip-install\/packages\/lib\/python3.10\/site-packages\/sqlalchemy\/orm\/context.py\", line 293, in orm_execute_statement\n    result = conn.execute(\n  File \"\/layers\/paketo-buildpacks_pip-install\/packages\/lib\/python3.10\/site-packages\/sqlalchemy\/engine\/base.py\", line 1416, in execute\n    return meth(\n  File \"\/layers\/paketo-buildpacks_pip-install\/packages\/lib\/python3.10\/site-packages\/sqlalchemy\/sql\/elements.py\", line 517, in _execute_on_connection\n    return connection._execute_clauseelement(\n  File \"\/layers\/paketo-buildpacks_pip-install\/packages\/lib\/python3.10\/site-packages\/sqlalchemy\/engine\/base.py\", line 1639, in _execute_clauseelement\n    ret = self._execute_context(\n  File \"\/layers\/paketo-buildpacks_pip-install\/packages\/lib\/python3.10\/site-packages\/sqlalchemy\/engine\/base.py\", line 1848, in _execute_context\n    return self._exec_single_context(\n  File \"\/layers\/paketo-buildpacks_pip-install\/packages\/lib\/python3.10\/site-packages\/sqlalchemy\/engine\/base.py\", line 1988, in _exec_single_context\n    self._handle_dbapi_exception(\n  File \"\/layers\/paketo-buildpacks_pip-install\/packages\/lib\/python3.10\/site-packages\/sqlalchemy\/engine\/base.py\", line 2344, in _handle_dbapi_exception\n    raise sqlalchemy_exception.with_traceback(exc_info[2]) from e\n  File \"\/layers\/paketo-buildpacks_pip-install\/packages\/lib\/python3.10\/site-packages\/sqlalchemy\/engine\/base.py\", line 1969, in _exec_single_context\n    self.dialect.do_execute(\n  File \"\/layers\/paketo-buildpacks_pip-install\/packages\/lib\/python3.10\/site-packages\/sqlalchemy\/engine\/default.py\", line 922, in do_execute\n    cursor.execute(statement, parameters)\n  File \"\/layers\/paketo-buildpacks_pip-install\/packages\/lib\/python3.10\/site-packages\/pymysql\/cursors.py\", line 153, in execute\n    result = self._query(query)\n  File \"\/layers\/paketo-buildpacks_pip-install\/packages\/lib\/python3.10\/site-packages\/pymysql\/cursors.py\", line 322, in _query\n    conn.query(q)\n  File \"\/layers\/paketo-buildpacks_pip-install\/packages\/lib\/python3.10\/site-packages\/pymysql\/connections.py\", line 558, in query\n    self._affected_rows = self._read_query_result(unbuffered=unbuffered)\n  File \"\/layers\/paketo-buildpacks_pip-install\/packages\/lib\/python3.10\/site-packages\/pymysql\/connections.py\", line 822, in _read_query_result\n    result.read()\n  File \"\/layers\/paketo-buildpacks_pip-install\/packages\/lib\/python3.10\/site-packages\/pymysql\/connections.py\", line 1200, in read\n    first_packet = self.connection._read_packet()\n  File \"\/layers\/paketo-buildpacks_pip-install\/packages\/lib\/python3.10\/site-packages\/pymysql\/connections.py\", line 739, in _read_packet\n    packet_header = self._read_bytes(4)\n  File \"\/layers\/paketo-buildpacks_pip-install\/packages\/lib\/python3.10\/site-packages\/pymysql\/connections.py\", line 795, in _read_bytes\n    raise err.OperationalError(\nsqlalchemy.exc.OperationalError: (pymysql.err.OperationalError) (2013, 'Lost connection to MySQL server during query')\n[SQL: SELECT users.uuid_user AS users_uuid_user, users.user AS users_user, users.password AS users_password, users.rol_uuid AS users_rol_uuid, users.is_active AS users_is_active, users.last_connection AS users_last_connection, users.created_at AS users_created_at, users.updated_at AS users_updated_at \nFROM users \nWHERE users.uuid_user = %(uuid_user_1)s]\n[parameters: {'uuid_user_1': 'a0ce19ba-1824-478e-800b-8d8ae78cc608'}]\n(Background on this error at: https:\/\/sqlalche.me\/e\/20\/e3q8)\n\nsrc\/test\/java\/payments\/post\/..\/..\/user\/token\/users-token-post.feature:9\n"},{"result":{"nanos":0,"millis":0.0,"status":"skipped"},"step":{"line":10,"prefix":"*","index":4,"text":"def token = $.access_token"}}],"line":5,"description":"","durationMillis":2239.201,"failed":true,"error":"status code was: 500, expected: 200, response time in milliseconds: 1243, url: https:\/\/funcoeback-dev-ceqh.3.us-1.fl0.io\/users\/token\/, response: \nTraceback (most recent call last):\n  File \"\/layers\/paketo-buildpacks_pip-install\/packages\/lib\/python3.10\/site-packages\/sqlalchemy\/engine\/base.py\", line 1969, in _exec_single_context\n    self.dialect.do_execute(\n  File \"\/layers\/paketo-buildpacks_pip-install\/packages\/lib\/python3.10\/site-packages\/sqlalchemy\/engine\/default.py\", line 922, in do_execute\n    cursor.execute(statement, parameters)\n  File \"\/layers\/paketo-buildpacks_pip-install\/packages\/lib\/python3.10\/site-packages\/pymysql\/cursors.py\", line 153, in execute\n    result = self._query(query)\n  File \"\/layers\/paketo-buildpacks_pip-install\/packages\/lib\/python3.10\/site-packages\/pymysql\/cursors.py\", line 322, in _query\n    conn.query(q)\n  File \"\/layers\/paketo-buildpacks_pip-install\/packages\/lib\/python3.10\/site-packages\/pymysql\/connections.py\", line 558, in query\n    self._affected_rows = self._read_query_result(unbuffered=unbuffered)\n  File \"\/layers\/paketo-buildpacks_pip-install\/packages\/lib\/python3.10\/site-packages\/pymysql\/connections.py\", line 822, in _read_query_result\n    result.read()\n  File \"\/layers\/paketo-buildpacks_pip-install\/packages\/lib\/python3.10\/site-packages\/pymysql\/connections.py\", line 1200, in read\n    first_packet = self.connection._read_packet()\n  File \"\/layers\/paketo-buildpacks_pip-install\/packages\/lib\/python3.10\/site-packages\/pymysql\/connections.py\", line 739, in _read_packet\n    packet_header = self._read_bytes(4)\n  File \"\/layers\/paketo-buildpacks_pip-install\/packages\/lib\/python3.10\/site-packages\/pymysql\/connections.py\", line 795, in _read_bytes\n    raise err.OperationalError(\npymysql.err.OperationalError: (2013, 'Lost connection to MySQL server during query')\n\nThe above exception was the direct cause of the following exception:\n\nTraceback (most recent call last):\n  File \"\/layers\/paketo-buildpacks_pip-install\/packages\/lib\/python3.10\/site-packages\/starlette\/middleware\/errors.py\", line 164, in __call__\n    await self.app(scope, receive, _send)\n  File \"\/layers\/paketo-buildpacks_pip-install\/packages\/lib\/python3.10\/site-packages\/starlette\/middleware\/exceptions.py\", line 62, in __call__\n    await wrap_app_handling_exceptions(self.app, conn)(scope, receive, send)\n  File \"\/layers\/paketo-buildpacks_pip-install\/packages\/lib\/python3.10\/site-packages\/starlette\/_exception_handler.py\", line 64, in wrapped_app\n    raise exc\n  File \"\/layers\/paketo-buildpacks_pip-install\/packages\/lib\/python3.10\/site-packages\/starlette\/_exception_handler.py\", line 53, in wrapped_app\n    await app(scope, receive, sender)\n  File \"\/layers\/paketo-buildpacks_pip-install\/packages\/lib\/python3.10\/site-packages\/starlette\/routing.py\", line 762, in __call__\n    await self.middleware_stack(scope, receive, send)\n  File \"\/layers\/paketo-buildpacks_pip-install\/packages\/lib\/python3.10\/site-packages\/starlette\/routing.py\", line 782, in app\n    await route.handle(scope, receive, send)\n  File \"\/layers\/paketo-buildpacks_pip-install\/packages\/lib\/python3.10\/site-packages\/starlette\/routing.py\", line 297, in handle\n    await self.app(scope, receive, send)\n  File \"\/layers\/paketo-buildpacks_pip-install\/packages\/lib\/python3.10\/site-packages\/starlette\/routing.py\", line 77, in app\n    await wrap_app_handling_exceptions(app, request)(scope, receive, send)\n  File \"\/layers\/paketo-buildpacks_pip-install\/packages\/lib\/python3.10\/site-packages\/starlette\/_exception_handler.py\", line 64, in wrapped_app\n    raise exc\n  File \"\/layers\/paketo-buildpacks_pip-install\/packages\/lib\/python3.10\/site-packages\/starlette\/_exception_handler.py\", line 53, in wrapped_app\n    await app(scope, receive, sender)\n  File \"\/layers\/paketo-buildpacks_pip-install\/packages\/lib\/python3.10\/site-packages\/starlette\/routing.py\", line 72, in app\n    response = await func(request)\n  File \"\/layers\/paketo-buildpacks_pip-install\/packages\/lib\/python3.10\/site-packages\/fastapi\/routing.py\", line 299, in app\n    raise e\n  File \"\/layers\/paketo-buildpacks_pip-install\/packages\/lib\/python3.10\/site-packages\/fastapi\/routing.py\", line 294, in app\n    raw_response = await run_endpoint_function(\n  File \"\/layers\/paketo-buildpacks_pip-install\/packages\/lib\/python3.10\/site-packages\/fastapi\/routing.py\", line 193, in run_endpoint_function\n    return await run_in_threadpool(dependant.call, **values)\n  File \"\/layers\/paketo-buildpacks_pip-install\/packages\/lib\/python3.10\/site-packages\/starlette\/concurrency.py\", line 40, in run_in_threadpool\n    return await anyio.to_thread.run_sync(func, *args)\n  File \"\/layers\/paketo-buildpacks_pip-install\/packages\/lib\/python3.10\/site-packages\/anyio\/to_thread.py\", line 56, in run_sync\n    return await get_async_backend().run_sync_in_worker_thread(\n  File \"\/layers\/paketo-buildpacks_pip-install\/packages\/lib\/python3.10\/site-packages\/anyio\/_backends\/_asyncio.py\", line 2134, in run_sync_in_worker_thread\n    return await future\n  File \"\/layers\/paketo-buildpacks_pip-install\/packages\/lib\/python3.10\/site-packages\/anyio\/_backends\/_asyncio.py\", line 851, in run\n    result = context.run(func, *args)\n  File \"\/workspace\/app\/routes\/user.py\", line 19, in get_token\n    if validate_user(user):\n  File \"\/workspace\/app\/func\/user.py\", line 26, in validate_user\n    r1=db.query(user_model).where(user_model.uuid_user==id_user).one()\n  File \"\/layers\/paketo-buildpacks_pip-install\/packages\/lib\/python3.10\/site-packages\/sqlalchemy\/orm\/query.py\", line 2798, in one\n    return self._iter().one()  # type: ignore\n  File \"\/layers\/paketo-buildpacks_pip-install\/packages\/lib\/python3.10\/site-packages\/sqlalchemy\/orm\/query.py\", line 2847, in _iter\n    result: Union[ScalarResult[_T], Result[_T]] = self.session.execute(\n  File \"\/layers\/paketo-buildpacks_pip-install\/packages\/lib\/python3.10\/site-packages\/sqlalchemy\/orm\/session.py\", line 2308, in execute\n    return self._execute_internal(\n  File \"\/layers\/paketo-buildpacks_pip-install\/packages\/lib\/python3.10\/site-packages\/sqlalchemy\/orm\/session.py\", line 2190, in _execute_internal\n    result: Result[Any] = compile_state_cls.orm_execute_statement(\n  File \"\/layers\/paketo-buildpacks_pip-install\/packages\/lib\/python3.10\/site-packages\/sqlalchemy\/orm\/context.py\", line 293, in orm_execute_statement\n    result = conn.execute(\n  File \"\/layers\/paketo-buildpacks_pip-install\/packages\/lib\/python3.10\/site-packages\/sqlalchemy\/engine\/base.py\", line 1416, in execute\n    return meth(\n  File \"\/layers\/paketo-buildpacks_pip-install\/packages\/lib\/python3.10\/site-packages\/sqlalchemy\/sql\/elements.py\", line 517, in _execute_on_connection\n    return connection._execute_clauseelement(\n  File \"\/layers\/paketo-buildpacks_pip-install\/packages\/lib\/python3.10\/site-packages\/sqlalchemy\/engine\/base.py\", line 1639, in _execute_clauseelement\n    ret = self._execute_context(\n  File \"\/layers\/paketo-buildpacks_pip-install\/packages\/lib\/python3.10\/site-packages\/sqlalchemy\/engine\/base.py\", line 1848, in _execute_context\n    return self._exec_single_context(\n  File \"\/layers\/paketo-buildpacks_pip-install\/packages\/lib\/python3.10\/site-packages\/sqlalchemy\/engine\/base.py\", line 1988, in _exec_single_context\n    self._handle_dbapi_exception(\n  File \"\/layers\/paketo-buildpacks_pip-install\/packages\/lib\/python3.10\/site-packages\/sqlalchemy\/engine\/base.py\", line 2344, in _handle_dbapi_exception\n    raise sqlalchemy_exception.with_traceback(exc_info[2]) from e\n  File \"\/layers\/paketo-buildpacks_pip-install\/packages\/lib\/python3.10\/site-packages\/sqlalchemy\/engine\/base.py\", line 1969, in _exec_single_context\n    self.dialect.do_execute(\n  File \"\/layers\/paketo-buildpacks_pip-install\/packages\/lib\/python3.10\/site-packages\/sqlalchemy\/engine\/default.py\", line 922, in do_execute\n    cursor.execute(statement, parameters)\n  File \"\/layers\/paketo-buildpacks_pip-install\/packages\/lib\/python3.10\/site-packages\/pymysql\/cursors.py\", line 153, in execute\n    result = self._query(query)\n  File \"\/layers\/paketo-buildpacks_pip-install\/packages\/lib\/python3.10\/site-packages\/pymysql\/cursors.py\", line 322, in _query\n    conn.query(q)\n  File \"\/layers\/paketo-buildpacks_pip-install\/packages\/lib\/python3.10\/site-packages\/pymysql\/connections.py\", line 558, in query\n    self._affected_rows = self._read_query_result(unbuffered=unbuffered)\n  File \"\/layers\/paketo-buildpacks_pip-install\/packages\/lib\/python3.10\/site-packages\/pymysql\/connections.py\", line 822, in _read_query_result\n    result.read()\n  File \"\/layers\/paketo-buildpacks_pip-install\/packages\/lib\/python3.10\/site-packages\/pymysql\/connections.py\", line 1200, in read\n    first_packet = self.connection._read_packet()\n  File \"\/layers\/paketo-buildpacks_pip-install\/packages\/lib\/python3.10\/site-packages\/pymysql\/connections.py\", line 739, in _read_packet\n    packet_header = self._read_bytes(4)\n  File \"\/layers\/paketo-buildpacks_pip-install\/packages\/lib\/python3.10\/site-packages\/pymysql\/connections.py\", line 795, in _read_bytes\n    raise err.OperationalError(\nsqlalchemy.exc.OperationalError: (pymysql.err.OperationalError) (2013, 'Lost connection to MySQL server during query')\n[SQL: SELECT users.uuid_user AS users_uuid_user, users.user AS users_user, users.password AS users_password, users.rol_uuid AS users_rol_uuid, users.is_active AS users_is_active, users.last_connection AS users_last_connection, users.created_at AS users_created_at, users.updated_at AS users_updated_at \nFROM users \nWHERE users.uuid_user = %(uuid_user_1)s]\n[parameters: {'uuid_user_1': 'a0ce19ba-1824-478e-800b-8d8ae78cc608'}]\n(Background on this error at: https:\/\/sqlalche.me\/e\/20\/e3q8)\n\nsrc\/test\/java\/payments\/post\/..\/..\/user\/token\/users-token-post.feature:9","tags":["token"],"executorName":"main","name":"Post a token","startTime":1709608527659,"refId":"[1:5]","endTime":1709608529902,"exampleIndex":-1}],"callDepth":1,"name":"JWT Token Feature","description":"","resultDate":"2024-03-04 10:15:30 p.\u202Fm.","durationMillis":2239.201,"passedCount":0}]},{"result":{"nanos":0,"millis":0.0,"status":"skipped"},"step":{"background":true,"line":6,"prefix":"*","index":1,"text":"header Authorization = \"Bearer \"  + token"}},{"result":{"nanos":0,"millis":0.0,"status":"skipped"},"step":{"background":true,"line":7,"prefix":"*","index":2,"text":"call read(\"..\/..\/enrolls\/post\/enrolls-post.feature@createrolls)\""}},{"result":{"nanos":0,"millis":0.0,"status":"skipped"},"step":{"background":true,"line":8,"prefix":"*","index":3,"text":"call read(\"..\/..\/concepts\/post\/concepts-post.feature@createconcepts)\""}},{"result":{"nanos":0,"millis":0.0,"status":"skipped"},"step":{"line":13,"prefix":"*","index":0,"text":"def randomamount =  Math.floor(Math.random() * 10) + 1"}},{"result":{"nanos":0,"millis":0.0,"status":"skipped"},"step":{"line":14,"prefix":"Given","index":1,"text":"url 'https:\/\/funcoeback-dev-ceqh.3.us-1.fl0.io\/roles\/'"}},{"result":{"nanos":0,"millis":0.0,"status":"skipped"},"step":{"line":15,"prefix":"And","index":2,"text":"request {\"enroll_uuid\": '#(enrollsid)', \"concept_uuid\": '#(conceptid)', \"amount\": '#(randomamount)'}"}},{"result":{"nanos":0,"millis":0.0,"status":"skipped"},"step":{"line":16,"prefix":"*","index":3,"text":"print randomamount"}},{"result":{"nanos":0,"millis":0.0,"status":"skipped"},"step":{"line":17,"prefix":"When","index":4,"text":"method post"}},{"result":{"nanos":0,"millis":0.0,"status":"skipped"},"step":{"line":18,"prefix":"Then","index":5,"text":"status 200"}},{"result":{"nanos":0,"millis":0.0,"status":"skipped"},"step":{"line":19,"prefix":"*","index":6,"text":"def paymentsId = $.uuid_payments"}}],"line":12,"description":"","durationMillis":3776.764,"failed":true,"error":"status code was: 500, expected: 200, response time in milliseconds: 1243, url: https:\/\/funcoeback-dev-ceqh.3.us-1.fl0.io\/users\/token\/, response: \nTraceback (most recent call last):\n  File \"\/layers\/paketo-buildpacks_pip-install\/packages\/lib\/python3.10\/site-packages\/sqlalchemy\/engine\/base.py\", line 1969, in _exec_single_context\n    self.dialect.do_execute(\n  File \"\/layers\/paketo-buildpacks_pip-install\/packages\/lib\/python3.10\/site-packages\/sqlalchemy\/engine\/default.py\", line 922, in do_execute\n    cursor.execute(statement, parameters)\n  File \"\/layers\/paketo-buildpacks_pip-install\/packages\/lib\/python3.10\/site-packages\/pymysql\/cursors.py\", line 153, in execute\n    result = self._query(query)\n  File \"\/layers\/paketo-buildpacks_pip-install\/packages\/lib\/python3.10\/site-packages\/pymysql\/cursors.py\", line 322, in _query\n    conn.query(q)\n  File \"\/layers\/paketo-buildpacks_pip-install\/packages\/lib\/python3.10\/site-packages\/pymysql\/connections.py\", line 558, in query\n    self._affected_rows = self._read_query_result(unbuffered=unbuffered)\n  File \"\/layers\/paketo-buildpacks_pip-install\/packages\/lib\/python3.10\/site-packages\/pymysql\/connections.py\", line 822, in _read_query_result\n    result.read()\n  File \"\/layers\/paketo-buildpacks_pip-install\/packages\/lib\/python3.10\/site-packages\/pymysql\/connections.py\", line 1200, in read\n    first_packet = self.connection._read_packet()\n  File \"\/layers\/paketo-buildpacks_pip-install\/packages\/lib\/python3.10\/site-packages\/pymysql\/connections.py\", line 739, in _read_packet\n    packet_header = self._read_bytes(4)\n  File \"\/layers\/paketo-buildpacks_pip-install\/packages\/lib\/python3.10\/site-packages\/pymysql\/connections.py\", line 795, in _read_bytes\n    raise err.OperationalError(\npymysql.err.OperationalError: (2013, 'Lost connection to MySQL server during query')\n\nThe above exception was the direct cause of the following exception:\n\nTraceback (most recent call last):\n  File \"\/layers\/paketo-buildpacks_pip-install\/packages\/lib\/python3.10\/site-packages\/starlette\/middleware\/errors.py\", line 164, in __call__\n    await self.app(scope, receive, _send)\n  File \"\/layers\/paketo-buildpacks_pip-install\/packages\/lib\/python3.10\/site-packages\/starlette\/middleware\/exceptions.py\", line 62, in __call__\n    await wrap_app_handling_exceptions(self.app, conn)(scope, receive, send)\n  File \"\/layers\/paketo-buildpacks_pip-install\/packages\/lib\/python3.10\/site-packages\/starlette\/_exception_handler.py\", line 64, in wrapped_app\n    raise exc\n  File \"\/layers\/paketo-buildpacks_pip-install\/packages\/lib\/python3.10\/site-packages\/starlette\/_exception_handler.py\", line 53, in wrapped_app\n    await app(scope, receive, sender)\n  File \"\/layers\/paketo-buildpacks_pip-install\/packages\/lib\/python3.10\/site-packages\/starlette\/routing.py\", line 762, in __call__\n    await self.middleware_stack(scope, receive, send)\n  File \"\/layers\/paketo-buildpacks_pip-install\/packages\/lib\/python3.10\/site-packages\/starlette\/routing.py\", line 782, in app\n    await route.handle(scope, receive, send)\n  File \"\/layers\/paketo-buildpacks_pip-install\/packages\/lib\/python3.10\/site-packages\/starlette\/routing.py\", line 297, in handle\n    await self.app(scope, receive, send)\n  File \"\/layers\/paketo-buildpacks_pip-install\/packages\/lib\/python3.10\/site-packages\/starlette\/routing.py\", line 77, in app\n    await wrap_app_handling_exceptions(app, request)(scope, receive, send)\n  File \"\/layers\/paketo-buildpacks_pip-install\/packages\/lib\/python3.10\/site-packages\/starlette\/_exception_handler.py\", line 64, in wrapped_app\n    raise exc\n  File \"\/layers\/paketo-buildpacks_pip-install\/packages\/lib\/python3.10\/site-packages\/starlette\/_exception_handler.py\", line 53, in wrapped_app\n    await app(scope, receive, sender)\n  File \"\/layers\/paketo-buildpacks_pip-install\/packages\/lib\/python3.10\/site-packages\/starlette\/routing.py\", line 72, in app\n    response = await func(request)\n  File \"\/layers\/paketo-buildpacks_pip-install\/packages\/lib\/python3.10\/site-packages\/fastapi\/routing.py\", line 299, in app\n    raise e\n  File \"\/layers\/paketo-buildpacks_pip-install\/packages\/lib\/python3.10\/site-packages\/fastapi\/routing.py\", line 294, in app\n    raw_response = await run_endpoint_function(\n  File \"\/layers\/paketo-buildpacks_pip-install\/packages\/lib\/python3.10\/site-packages\/fastapi\/routing.py\", line 193, in run_endpoint_function\n    return await run_in_threadpool(dependant.call, **values)\n  File \"\/layers\/paketo-buildpacks_pip-install\/packages\/lib\/python3.10\/site-packages\/starlette\/concurrency.py\", line 40, in run_in_threadpool\n    return await anyio.to_thread.run_sync(func, *args)\n  File \"\/layers\/paketo-buildpacks_pip-install\/packages\/lib\/python3.10\/site-packages\/anyio\/to_thread.py\", line 56, in run_sync\n    return await get_async_backend().run_sync_in_worker_thread(\n  File \"\/layers\/paketo-buildpacks_pip-install\/packages\/lib\/python3.10\/site-packages\/anyio\/_backends\/_asyncio.py\", line 2134, in run_sync_in_worker_thread\n    return await future\n  File \"\/layers\/paketo-buildpacks_pip-install\/packages\/lib\/python3.10\/site-packages\/anyio\/_backends\/_asyncio.py\", line 851, in run\n    result = context.run(func, *args)\n  File \"\/workspace\/app\/routes\/user.py\", line 19, in get_token\n    if validate_user(user):\n  File \"\/workspace\/app\/func\/user.py\", line 26, in validate_user\n    r1=db.query(user_model).where(user_model.uuid_user==id_user).one()\n  File \"\/layers\/paketo-buildpacks_pip-install\/packages\/lib\/python3.10\/site-packages\/sqlalchemy\/orm\/query.py\", line 2798, in one\n    return self._iter().one()  # type: ignore\n  File \"\/layers\/paketo-buildpacks_pip-install\/packages\/lib\/python3.10\/site-packages\/sqlalchemy\/orm\/query.py\", line 2847, in _iter\n    result: Union[ScalarResult[_T], Result[_T]] = self.session.execute(\n  File \"\/layers\/paketo-buildpacks_pip-install\/packages\/lib\/python3.10\/site-packages\/sqlalchemy\/orm\/session.py\", line 2308, in execute\n    return self._execute_internal(\n  File \"\/layers\/paketo-buildpacks_pip-install\/packages\/lib\/python3.10\/site-packages\/sqlalchemy\/orm\/session.py\", line 2190, in _execute_internal\n    result: Result[Any] = compile_state_cls.orm_execute_statement(\n  File \"\/layers\/paketo-buildpacks_pip-install\/packages\/lib\/python3.10\/site-packages\/sqlalchemy\/orm\/context.py\", line 293, in orm_execute_statement\n    result = conn.execute(\n  File \"\/layers\/paketo-buildpacks_pip-install\/packages\/lib\/python3.10\/site-packages\/sqlalchemy\/engine\/base.py\", line 1416, in execute\n    return meth(\n  File \"\/layers\/paketo-buildpacks_pip-install\/packages\/lib\/python3.10\/site-packages\/sqlalchemy\/sql\/elements.py\", line 517, in _execute_on_connection\n    return connection._execute_clauseelement(\n  File \"\/layers\/paketo-buildpacks_pip-install\/packages\/lib\/python3.10\/site-packages\/sqlalchemy\/engine\/base.py\", line 1639, in _execute_clauseelement\n    ret = self._execute_context(\n  File \"\/layers\/paketo-buildpacks_pip-install\/packages\/lib\/python3.10\/site-packages\/sqlalchemy\/engine\/base.py\", line 1848, in _execute_context\n    return self._exec_single_context(\n  File \"\/layers\/paketo-buildpacks_pip-install\/packages\/lib\/python3.10\/site-packages\/sqlalchemy\/engine\/base.py\", line 1988, in _exec_single_context\n    self._handle_dbapi_exception(\n  File \"\/layers\/paketo-buildpacks_pip-install\/packages\/lib\/python3.10\/site-packages\/sqlalchemy\/engine\/base.py\", line 2344, in _handle_dbapi_exception\n    raise sqlalchemy_exception.with_traceback(exc_info[2]) from e\n  File \"\/layers\/paketo-buildpacks_pip-install\/packages\/lib\/python3.10\/site-packages\/sqlalchemy\/engine\/base.py\", line 1969, in _exec_single_context\n    self.dialect.do_execute(\n  File \"\/layers\/paketo-buildpacks_pip-install\/packages\/lib\/python3.10\/site-packages\/sqlalchemy\/engine\/default.py\", line 922, in do_execute\n    cursor.execute(statement, parameters)\n  File \"\/layers\/paketo-buildpacks_pip-install\/packages\/lib\/python3.10\/site-packages\/pymysql\/cursors.py\", line 153, in execute\n    result = self._query(query)\n  File \"\/layers\/paketo-buildpacks_pip-install\/packages\/lib\/python3.10\/site-packages\/pymysql\/cursors.py\", line 322, in _query\n    conn.query(q)\n  File \"\/layers\/paketo-buildpacks_pip-install\/packages\/lib\/python3.10\/site-packages\/pymysql\/connections.py\", line 558, in query\n    self._affected_rows = self._read_query_result(unbuffered=unbuffered)\n  File \"\/layers\/paketo-buildpacks_pip-install\/packages\/lib\/python3.10\/site-packages\/pymysql\/connections.py\", line 822, in _read_query_result\n    result.read()\n  File \"\/layers\/paketo-buildpacks_pip-install\/packages\/lib\/python3.10\/site-packages\/pymysql\/connections.py\", line 1200, in read\n    first_packet = self.connection._read_packet()\n  File \"\/layers\/paketo-buildpacks_pip-install\/packages\/lib\/python3.10\/site-packages\/pymysql\/connections.py\", line 739, in _read_packet\n    packet_header = self._read_bytes(4)\n  File \"\/layers\/paketo-buildpacks_pip-install\/packages\/lib\/python3.10\/site-packages\/pymysql\/connections.py\", line 795, in _read_bytes\n    raise err.OperationalError(\nsqlalchemy.exc.OperationalError: (pymysql.err.OperationalError) (2013, 'Lost connection to MySQL server during query')\n[SQL: SELECT users.uuid_user AS users_uuid_user, users.user AS users_user, users.password AS users_password, users.rol_uuid AS users_rol_uuid, users.is_active AS users_is_active, users.last_connection AS users_last_connection, users.created_at AS users_created_at, users.updated_at AS users_updated_at \nFROM users \nWHERE users.uuid_user = %(uuid_user_1)s]\n[parameters: {'uuid_user_1': 'a0ce19ba-1824-478e-800b-8d8ae78cc608'}]\n(Background on this error at: https:\/\/sqlalche.me\/e\/20\/e3q8)\n\nsrc\/test\/java\/payments\/post\/..\/..\/user\/token\/users-token-post.feature:9\nsrc\/test\/java\/payments\/post\/create_payments-post.feature:5","tags":["createpayments"],"executorName":"main","name":"create new payments","startTime":1709608526151,"refId":"[1:12]","endTime":1709608529969,"exampleIndex":-1}],"callDepth":0,"name":"Post a payments","description":"","resultDate":"2024-03-04 10:15:30 p.\u202Fm.","durationMillis":3776.764,"passedCount":0}